Workbook
Name AbsenteeDays: 'Random Data'!$M:$M
Name CostofEmployeeTurnover: 'Random Data'!$AA:$AA
Name EmployeeID: 'Random Data'!$A:$A
Name ExitDate: 'Random Data'!$G:$G
Name Gender: 'Random Data'!$N:$N
Name HireDate: 'Random Data'!$E:$E
Name ID: 'Random Data'!$A:$A
Name JobPostingDate: 'Random Data'!$D:$D
Name JobTitle: 'Random Data'!$C:$C
Name JoinDate: 'Random Data'!$F:$F
Name Onboardingcost: 'Random Data'!$W:$W
Name Pasted: #REF!
Name RecruitmentCost: 'Random Data'!$I:$I
Name RecruitmentCycleTime: 'Random Data'!$S:$S
Name Slicer_Department: #N/A
Name Slicer_Gender: #N/A
Name Slicer_Job_Title: #N/A
Name Slicer_Status: #N/A
Name Slicer_Training_Completion_Status: #N/A
Name Slicer_year_of_joining: #N/A
Name Status: 'Random Data'!$H:$H
Name Table2: #REF!
Name Timetofill: 'Random Data'!$P:$P
Name Timetoonboard: 'Random Data'!$Q:$Q
Name TotalTenure: 'Random Data'!#REF!
Name TotalTenureinM: 'Random Data'!$R:$R
Name TotalWorkDays: 'Random Data'!$L:$L
Name TrainingCompletionStatus: 'Random Data'!$K:$K
Name TrainingCost: 'Random Data'!$O:$O
Name TrainingProgram: 'Random Data'!$J:$J

Sheet Random Data
A1: Employee ID | B1: Department | C1: Job Title | D1: Job Posting Date | E1: Hire Date | F1: Join Date | G1: Exit Date | H1: Status | I1: Recruitment Cost | J1: Training Program | K1: Training Completion Status | L1: Total Work Days | M1: Absentee Days | N1: Gender | O1: Training Cost | P1: Time to Fill | Q1: Time to Onboard | R1: Total Tenure in M | S1: Recruitment Cycle Time | T1: Onboarding Efficiency Rate | U1: Individual Onboard Efficiency Rate | V1: Recruitment Lag | W1: Onboarding Cost | X1: Absenteeism Rate | Y1: Year of Joining | Z1: Retention Status | AA1: Cost of Employee Turnover | AB1: Column1
A2: ="E" & TEXT(ROW(A1), "000") -> E001 | B2: {=INDEX(sheet2!$A$2:$A$6, RANDBETWEEN(1, 5))} -> Finance | C2: =_xlfn.XLOOKUP(Table1[[#This Row],[Department]],sheet2!$A$2:$A$6,sheet2!$B$2:$B$6,_xleta.NA,0) -> Finance Manager | D2: =DATE(RANDBETWEEN(2018, 2022), RANDBETWEEN(1, 12), RANDBETWEEN(1, 28)) -> 43484 | E2: =Table1[[#This Row],[Job Posting Date]]+ RANDBETWEEN(15, 90) -> 43512 | F2: =Table1[[#This Row],[Hire Date]]+ RANDBETWEEN(1, 15) -> 43517 | G2: =IF(RAND() < 0.5, Table1[[#This Row],[Join Date]]+ RANDBETWEEN(30, TODAY()- Table1[[#This Row],[Join Date]]), "-") -> - | H2: =IF(Table1[[#This Row],[Exit Date]]= "-", "Active", "Exited") -> Active | I2: =RANDBETWEEN(1500, 5000) -> 1954 | J2: {=INDEX(sheet2!$C$2:$C$6, RANDBETWEEN(1, 5))} -> Conflict Resolution | K2: =IF(RAND() < 0.7, "Completed", "Not Completed") -> Completed | L2: 260 | M2: =RANDBETWEEN(0, 20) -> 20 | N2: =CHOOSE(RANDBETWEEN(1, 3), "Male", "Female", "Other") -> Male | O2: =RANDBETWEEN(1200, 2500) -> 1242 | P2: =Table1[[#This Row],[Hire Date]]-Table1[[#This Row],[Job Posting Date]] -> 28 | Q2: =Table1[[#This Row],[Join Date]]-Table1[[#This Row],[Hire Date]] -> 5 | R2: =(IF(Table1[[#This Row],[Status]]="Exited",Table1[[#This Row],[Exit Date]]-Table1[[#This Row],[Join Date]],TODAY()-Table1[[#This Row],[Join Date]]))/30 -> 72.2 | S2: =Table1[[#This Row],[Hire Date]]-Table1[[#This Row],[Job Posting Date]] -> 28 | T2: =Table1[[#This Row],[Time to Onboard]]/Table1[[#This Row],[Time to Fill]]*100 -> 17.857143 | U2: =Table1[[#This Row],[Time to Onboard]]/Table1[[#This Row],[Time to Fill]]*100 -> 17.857143 | V2: =Table1[[#This Row],[Join Date]]-Table1[[#This Row],[Job Posting Date]] -> 33 | W2: =RANDBETWEEN(100,200) -> 125 | X2: =Table1[[#This Row],[Absentee Days]]/Table1[[#This Row],[Total Work Days]]*100 -> 7.6923077 | Y2: =YEAR(Table1[[#This Row],[Join Date]]) -> 2019 | Z2: =IF(Table1[[#This Row],[Status]]="Active",1,0) -> 1 | AA2: =IF(Table1[[#This Row],[Status]]="Exited",Table1[[#This Row],[Recruitment Cost]]+Table1[[#This Row],[Onboarding Cost]]+Table1[[#This Row],[Training Cost]],0) -> 0
A3: ="E" & TEXT(ROW(A2), "000") -> E002 | B3: {=INDEX(sheet2!$A$2:$A$6, RANDBETWEEN(1, 5))} -> Analytics | C3: =_xlfn.XLOOKUP(Table1[[#This Row],[Department]],sheet2!$A$2:$A$6,sheet2!$B$2:$B$6,_xleta.NA,0) -> Data Analyst | D3: =DATE(RANDBETWEEN(2018, 2022), RANDBETWEEN(1, 12), RANDBETWEEN(1, 28)) -> 43639 | E3: =Table1[[#This Row],[Job Posting Date]]+ RANDBETWEEN(15, 90) -> 43716 | F3: =Table1[[#This Row],[Hire Date]]+ RANDBETWEEN(1, 15) -> 43717 | G3: =IF(RAND() < 0.5, Table1[[#This Row],[Join Date]]+ RANDBETWEEN(30, TODAY()- Table1[[#This Row],[Join Date]]), "-") -> - | H3: =IF(Table1[[#This Row],[Exit Date]]= "-", "Active", "Exited") -> Active | I3: =RANDBETWEEN(1500, 5000) -> 2349 | J3: {=INDEX(sheet2!$C$2:$C$6, RANDBETWEEN(1, 5))} -> Ethics and Responsibilities | K3: =IF(RAND() < 0.7, "Completed", "Not Completed") -> Not Completed | L3: 260 | M3: =RANDBETWEEN(0, 20) -> 15 | N3: =CHOOSE(RANDBETWEEN(1, 3), "Male", "Female", "Other") -> Female | O3: =RANDBETWEEN(1200, 2500) -> 2155 | P3: =Table1[[#This Row],[Hire Date]]-Table1[[#This Row],[Job Posting Date]] -> 77 | Q3: =Table1[[#This Row],[Join Date]]-Table1[[#This Row],[Hire Date]] -> 1 | R3: =(IF(Table1[[#This Row],[Status]]="Exited",Table1[[#This Row],[Exit Date]]-Table1[[#This Row],[Join Date]],TODAY()-Table1[[#This Row],[Join Date]]))/30 -> 65.533333 | S3: =Table1[[#This Row],[Hire Date]]-Table1[[#This Row],[Job Posting Date]] -> 77 | T3: =Table1[[#This Row],[Time to Onboard]]/Table1[[#This Row],[Time to Fill]]*100 -> 1.2987013 | U3: =Table1[[#This Row],[Time to Onboard]]/Table1[[#This Row],[Time to Fill]]*100 -> 1.2987013 | V3: =Table1[[#This Row],[Join Date]]-Table1[[#This Row],[Job Posting Date]] -> 78 | W3: =RANDBETWEEN(100,200) -> 191 | X3: =Table1[[#This Row],[Absentee Days]]/Table1[[#This Row],[Total Work Days]]*100 -> 5.7692308 | Y3: =YEAR(Table1[[#This Row],[Join Date]]) -> 2019 | Z3: =IF(Table1[[#This Row],[Status]]="Active",1,0) -> 1 | AA3: =IF(Table1[[#This Row],[Status]]="Exited",Table1[[#This Row],[Recruitment Cost]]+Table1[[#This Row],[Onboarding Cost]]+Table1[[#This Row],[Training Cost]],0) -> 0
A4: ="E" & TEXT(ROW(A3), "000") -> E003 | B4: {=INDEX(sheet2!$A$2:$A$6, RANDBETWEEN(1, 5))} -> Sales | C4: =_xlfn.XLOOKUP(Table1[[#This Row],[Department]],sheet2!$A$2:$A$6,sheet2!$B$2:$B$6,_xleta.NA,0) -> Marketing Manager | D4: =DATE(RANDBETWEEN(2018, 2022), RANDBETWEEN(1, 12), RANDBETWEEN(1, 28)) -> 44299 | E4: =Table1[[#This Row],[Job Posting Date]]+ RANDBETWEEN(15, 90) -> 44331 | F4: =Table1[[#This Row],[Hire Date]]+ RANDBETWEEN(1, 15) -> 44337 | G4: =IF(RAND() < 0.5, Table1[[#This Row],[Join Date]]+ RANDBETWEEN(30, TODAY()- Table1[[#This Row],[Join Date]]), "-") -> 44717 | H4: =IF(Table1[[#This Row],[Exit Date]]= "-", "Active", "Exited") -> Exited | I4: =RANDBETWEEN(1500, 5000) -> 2385 | J4: {=INDEX(sheet2!$C$2:$C$6, RANDBETWEEN(1, 5))} -> Conflict Resolution | K4: =IF(RAND() < 0.7, "Completed", "Not Completed") -> Not Completed | L4: 260 | M4: =RANDBETWEEN(0, 20) -> 0 | N4: =CHOOSE(RANDBETWEEN(1, 3), "Male", "Female", "Other") -> Male | O4: =RANDBETWEEN(1200, 2500) -> 1851 | P4: =Table1[[#This Row],[Hire Date]]-Table1[[#This Row],[Job Posting Date]] -> 32 | Q4: =Table1[[#This Row],[Join Date]]-Table1[[#This Row],[Hire Date]] -> 6 | R4: =(IF(Table1[[#This Row],[Status]]="Exited",Table1[[#This Row],[Exit Date]]-Table1[[#This Row],[Join Date]],TODAY()-Table1[[#This Row],[Join Date]]))/30 -> 12.666667 | S4: =Table1[[#This Row],[Hire Date]]-Table1[[#This Row],[Job Posting Date]] -> 32 | T4: =Table1[[#This Row],[Time to Onboard]]/Table1[[#This Row],[Time to Fill]]*100 -> 18.75 | U4: =Table1[[#This Row],[Time to Onboard]]/Table1[[#This Row],[Time to Fill]]*100 -> 18.75 | V4: =Table1[[#This Row],[Join Date]]-Table1[[#This Row],[Job Posting Date]] -> 38 | W4: =RANDBETWEEN(100,200) -> 182 | X4: =Table1[[#This Row],[Absentee Days]]/Table1[[#This Row],[Total Work Days]]*100 -> 0 | Y4: =YEAR(Table1[[#This Row],[Join Date]]) -> 2021 | Z4: =IF(Table1[[#This Row],[Status]]="Active",1,0) -> 0 | AA4: =IF(Table1[[#This Row],[Status]]="Exited",Table1[[#This Row],[Recruitment Cost]]+Table1[[#This Row],[Onboarding Cost]]+Table1[[#This Row],[Training Cost]],0) -> 4418
A5: ="E" & TEXT(ROW(A4), "000") -> E004 | B5: {=INDEX(sheet2!$A$2:$A$6, RANDBETWEEN(1, 5))} -> HR | C5: =_xlfn.XLOOKUP(Table1[[#This Row],[Department]],sheet2!$A$2:$A$6,sheet2!$B$2:$B$6,_xleta.NA,0) -> HR Manager | D5: =DATE(RANDBETWEEN(2018, 2022), RANDBETWEEN(1, 12), RANDBETWEEN(1, 28)) -> 43591 | E5: =Table1[[#This Row],[Job Posting Date]]+ RANDBETWEEN(15, 90) -> 43668 | F5: =Table1[[#This Row],[Hire Date]]+ RANDBETWEEN(1, 15) -> 43676 | G5: =IF(RAND() < 0.5, Table1[[#This Row],[Join Date]]+ RANDBETWEEN(30, TODAY()- Table1[[#This Row],[Join Date]]), "-") -> - | H5: =IF(Table1[[#This Row],[Exit Date]]= "-", "Active", "Exited") -> Active | I5: =RANDBETWEEN(1500, 5000) -> 1788 | J5: {=INDEX(sheet2!$C$2:$C$6, RANDBETWEEN(1, 5))} -> Advanced Excel Skills | K5: =IF(RAND() < 0.7, "Completed", "Not Completed") -> Completed | L5: 260 | M5: =RANDBETWEEN(0, 20) -> 1 | N5: =CHOOSE(RANDBETWEEN(1, 3), "Male", "Female", "Other") -> Female | O5: =RANDBETWEEN(1200, 2500) -> 2449 | P5: =Table1[[#This Row],[Hire Date]]-Table1[[#This Row],[Job Posting Date]] -> 77 | Q5: =Table1[[#This Row],[Join Date]]-Table1[[#This Row],[Hire Date]] -> 8 | R5: =(IF(Table1[[#This Row],[Status]]="Exited",Table1[[#This Row],[Exit Date]]-Table1[[#This Row],[Join Date]],TODAY()-Table1[[#This Row],[Join Date]]))/30 -> 66.9 | S5: =Table1[[#This Row],[Hire Date]]-Table1[[#This Row],[Job Posting Date]] -> 77 | T5: =Table1[[#This Row],[Time to Onboard]]/Table1[[#This Row],[Time to Fill]]*100 -> 10.38961 | U5: =Table1[[#This Row],[Time to Onboard]]/Table1[[#This Row],[Time to Fill]]*100 -> 10.38961 | V5: =Table1[[#This Row],[Join Date]]-Table1[[#This Row],[Job Posting Date]] -> 85 | W5: =RANDBETWEEN(100,200) -> 177 | X5: =Table1[[#This Row],[Absentee Days]]/Table1[[#This Row],[Total Work Days]]*100 -> 0.38461538 | Y5: =YEAR(Table1[[#This Row],[Join Date]]) -> 2019 | Z5: =IF(Table1[[#This Row],[Status]]="Active",1,0) -> 1 | AA5: =IF(Table1[[#This Row],[Status]]="Exited",Table1[[#This Row],[Recruitment Cost]]+Table1[[#This Row],[Onboarding Cost]]+Table1[[#This Row],[Training Cost]],0) -> 0 | AD5: Turnover Rate | AE5: Retention Rate | AF5: Training completion rate | AG5: Average time to fill | AH5: Average employee tenure
A6: ="E" & TEXT(ROW(A5), "000") -> E005 | B6: {=INDEX(sheet2!$A$2:$A$6, RANDBETWEEN(1, 5))} -> Sales | C6: =_xlfn.XLOOKUP(Table1[[#This Row],[Department]],sheet2!$A$2:$A$6,sheet2!$B$2:$B$6,_xleta.NA,0) -> Marketing Manager | D6: =DATE(RANDBETWEEN(2018, 2022), RANDBETWEEN(1, 12), RANDBETWEEN(1, 28)) -> 43922 | E6: =Table1[[#This Row],[Job Posting Date]]+ RANDBETWEEN(15, 90) -> 43981 | F6: =Table1[[#This Row],[Hire Date]]+ RANDBETWEEN(1, 15) -> 43984 | G6: =IF(RAND() < 0.5, Table1[[#This Row],[Join Date]]+ RANDBETWEEN(30, TODAY()- Table1[[#This Row],[Join Date]]), "-") -> 44406 | H6: =IF(Table1[[#This Row],[Exit Date]]= "-", "Active", "Exited") -> Exited | I6: =RANDBETWEEN(1500, 5000) -> 4771 | J6: {=INDEX(sheet2!$C$2:$C$6, RANDBETWEEN(1, 5))} -> Conflict Resolution | K6: =IF(RAND() < 0.7, "Completed", "Not Completed") -> Completed | L6: 260 | M6: =RANDBETWEEN(0, 20) -> 8 | N6: =CHOOSE(RANDBETWEEN(1, 3), "Male", "Female", "Other") -> Male | O6: =RANDBETWEEN(1200, 2500) -> 1201 | P6: =Table1[[#This Row],[Hire Date]]-Table1[[#This Row],[Job Posting Date]] -> 59 | Q6: =Table1[[#This Row],[Join Date]]-Table1[[#This Row],[Hire Date]] -> 3 | R6: =(IF(Table1[[#This Row],[Status]]="Exited",Table1[[#This Row],[Exit Date]]-Table1[[#This Row],[Join Date]],TODAY()-Table1[[#This Row],[Join Date]]))/30 -> 14.066667 | S6: =Table1[[#This Row],[Hire Date]]-Table1[[#This Row],[Job Posting Date]] -> 59 | T6: =Table1[[#This Row],[Time to Onboard]]/Table1[[#This Row],[Time to Fill]]*100 -> 5.0847458 | U6: =Table1[[#This Row],[Time to Onboard]]/Table1[[#This Row],[Time to Fill]]*100 -> 5.0847458 | V6: =Table1[[#This Row],[Join Date]]-Table1[[#This Row],[Job Posting Date]] -> 62 | W6: =RANDBETWEEN(100,200) -> 141 | X6: =Table1[[#This Row],[Absentee Days]]/Table1[[#This Row],[Total Work Days]]*100 -> 3.0769231 | Y6: =YEAR(Table1[[#This Row],[Join Date]]) -> 2020 | Z6: =IF(Table1[[#This Row],[Status]]="Active",1,0) -> 0 | AA6: =IF(Table1[[#This Row],[Status]]="Exited",Table1[[#This Row],[Recruitment Cost]]+Table1[[#This Row],[Onboarding Cost]]+Table1[[#This Row],[Training Cost]],0) -> 6113 | AD6: =(COUNTIF(Status,"Exited") / COUNTA(Status)) * 100 -> 46.613546 | AE6: =((COUNTIF(Status,"Active")) / COUNTA(Status)) * 100 -> 52.988048 | AF6: =(COUNTIF(TrainingCompletionStatus,"Completed") / COUNTA(TrainingCompletionStatus)) * 100 -> 72.50996 | AG6: =AVERAGE(Timetofill) -> 55.356 | AH6: =AVERAGE(TotalTenureinM) -> 41.168407
A7: ="E" & TEXT(ROW(A6), "000") -> E006 | B7: {=INDEX(sheet2!$A$2:$A$6, RANDBETWEEN(1, 5))} -> IT | C7: =_xlfn.XLOOKUP(Table1[[#This Row],[Department]],sheet2!$A$2:$A$6,sheet2!$B$2:$B$6,_xleta.NA,0) -> Software Engineer | D7: =DATE(RANDBETWEEN(2018, 2022), RANDBETWEEN(1, 12), RANDBETWEEN(1, 28)) -> 44693 | E7: =Table1[[#This Row],[Job Posting Date]]+ RANDBETWEEN(15, 90) -> 44731 | F7: =Table1[[#This Row],[Hire Date]]+ RANDBETWEEN(1, 15) -> 44746 | G7: =IF(RAND() < 0.5, Table1[[#This Row],[Join Date]]+ RANDBETWEEN(30, TODAY()- Table1[[#This Row],[Join Date]]), "-") -> - | H7: =IF(Table1[[#This Row],[Exit Date]]= "-", "Active", "Exited") -> Active | I7: =RANDBETWEEN(1500, 5000) -> 2404 | J7: {=INDEX(sheet2!$C$2:$C$6, RANDBETWEEN(1, 5))} -> Ethics and Responsibilities | K7: =IF(RAND() < 0.7, "Completed", "Not Completed") -> Not Completed | L7: 260 | M7: =RANDBETWEEN(0, 20) -> 12 | N7: =CHOOSE(RANDBETWEEN(1, 3), "Male", "Female", "Other") -> Other | O7: =RANDBETWEEN(1200, 2500) -> 2457 | P7: =Table1[[#This Row],[Hire Date]]-Table1[[#This Row],[Job Posting Date]] -> 38 | Q7: =Table1[[#This Row],[Join Date]]-Table1[[#This Row],[Hire Date]] -> 15 | R7: =(IF(Table1[[#This Row],[Status]]="Exited",Table1[[#This Row],[Exit Date]]-Table1[[#This Row],[Join Date]],TODAY()-Table1[[#This Row],[Join Date]]))/30 -> 31.233333 | S7: =Table1[[#This Row],[Hire Date]]-Table1[[#This Row],[Job Posting Date]] -> 38 | T7: =Table1[[#This Row],[Time to Onboard]]/Table1[[#This Row],[Time to Fill]]*100 -> 39.473684 | U7: =Table1[[#This Row],[Time to Onboard]]/Table1[[#This Row],[Time to Fill]]*100 -> 39.473684 | V7: =Table1[[#This Row],[Join Date]]-Table1[[#This Row],[Job Posting Date]] -> 53 | W7: =RANDBETWEEN(100,200) -> 173 | X7: =Table1[[#This Row],[Absentee Days]]/Table1[[#This Row],[Total Work Days]]*100 -> 4.6153846 | Y7: =YEAR(Table1[[#This Row],[Join Date]]) -> 2022 | Z7: =IF(Table1[[#This Row],[Status]]="Active",1,0) -> 1 | AA7: =IF(Table1[[#This Row],[Status]]="Exited",Table1[[#This Row],[Recruitment Cost]]+Table1[[#This Row],[Onboarding Cost]]+Table1[[#This Row],[Training Cost]],0) -> 0
A8: ="E" & TEXT(ROW(A7), "000") -> E007 | B8: {=INDEX(sheet2!$A$2:$A$6, RANDBETWEEN(1, 5))} -> IT | C8: =_xlfn.XLOOKUP(Table1[[#This Row],[Department]],sheet2!$A$2:$A$6,sheet2!$B$2:$B$6,_xleta.NA,0) -> Software Engineer | D8: =DATE(RANDBETWEEN(2018, 2022), RANDBETWEEN(1, 12), RANDBETWEEN(1, 28)) -> 43398 | E8: =Table1[[#This Row],[Job Posting Date]]+ RANDBETWEEN(15, 90) -> 43456 | F8: =Table1[[#This Row],[Hire Date]]+ RANDBETWEEN(1, 15) -> 43466 | G8: =IF(RAND() < 0.5, Table1[[#This Row],[Join Date]]+ RANDBETWEEN(30, TODAY()- Table1[[#This Row],[Join Date]]), "-") -> 44530 | H8: =IF(Table1[[#This Row],[Exit Date]]= "-", "Active", "Exited") -> Exited | I8: =RANDBETWEEN(1500, 5000) -> 4443 | J8: {=INDEX(sheet2!$C$2:$C$6, RANDBETWEEN(1, 5))} -> Advanced Excel Skills | K8: =IF(RAND() < 0.7, "Completed", "Not Completed") -> Completed | L8: 260 | M8: =RANDBETWEEN(0, 20) -> 14 | N8: =CHOOSE(RANDBETWEEN(1, 3), "Male", "Female", "Other") -> Male | O8: =RANDBETWEEN(1200, 2500) -> 1677 | P8: =Table1[[#This Row],[Hire Date]]-Table1[[#This Row],[Job Posting Date]] -> 58 | Q8: =Table1[[#This Row],[Join Date]]-Table1[[#This Row],[Hire Date]] -> 10 | R8: =(IF(Table1[[#This Row],[Status]]="Exited",Table1[[#This Row],[Exit Date]]-Table1[[#This Row],[Join Date]],TODAY()-Table1[[#This Row],[Join Date]]))/30 -> 35.466667 | S8: =Table1[[#This Row],[Hire Date]]-Table1[[#This Row],[Job Posting Date]] -> 58 | T8: =Table1[[#This Row],[Time to Onboard]]/Table1[[#This Row],[Time to Fill]]*100 -> 17.241379 | U8: =Table1[[#This Row],[Time to Onboard]]/Table1[[#This Row],[Time to Fill]]*100 -> 17.241379 | V8: =Table1[[#This Row],[Join Date]]-Table1[[#This Row],[Job Posting Date]] -> 68 | W8: =RANDBETWEEN(100,200) -> 191 | X8: =Table1[[#This Row],[Absentee Days]]/Table1[[#This Row],[Total Work Days]]*100 -> 5.3846154 | Y8: =YEAR(Table1[[#This Row],[Join Date]]) -> 2019 | Z8: =IF(Table1[[#This Row],[Status]]="Active",1,0) -> 0 | AA8: =IF(Table1[[#This Row],[Status]]="Exited",Table1[[#This Row],[Recruitment Cost]]+Table1[[#This Row],[Onboarding Cost]]+Table1[[#This Row],[Training Cost]],0) -> 6311
A9: ="E" & TEXT(ROW(A8), "000") -> E008 | B9: {=INDEX(sheet2!$A$2:$A$6, RANDBETWEEN(1, 5))} -> Finance | C9: =_xlfn.XLOOKUP(Table1[[#This Row],[Department]],sheet2!$A$2:$A$6,sheet2!$B$2:$B$6,_xleta.NA,0) -> Finance Manager | D9: =DATE(RANDBETWEEN(2018, 2022), RANDBETWEEN(1, 12), RANDBETWEEN(1, 28)) -> 43917 | E9: =Table1[[#This Row],[Job Posting Date]]+ RANDBETWEEN(15, 90) -> 44006 | F9: =Table1[[#This Row],[Hire Date]]+ RANDBETWEEN(1, 15) -> 44016 | G9: =IF(RAND() < 0.5, Table1[[#This Row],[Join Date]]+ RANDBETWEEN(30, TODAY()- Table1[[#This Row],[Join Date]]), "-") -> - | H9: =IF(Table1[[#This Row],[Exit Date]]= "-", "Active", "Exited") -> Active | I9: =RANDBETWEEN(1500, 5000) -> 2192 | J9: {=INDEX(sheet2!$C$2:$C$6, RANDBETWEEN(1, 5))} -> Conflict Resolution | K9: =IF(RAND() < 0.7, "Completed", "Not Completed") -> Completed | L9: 260 | M9: =RANDBETWEEN(0, 20) -> 11 | N9: =CHOOSE(RANDBETWEEN(1, 3), "Male", "Female", "Other") -> Female | O9: =RANDBETWEEN(1200, 2500) -> 1832 | P9: =Table1[[#This Row],[Hire Date]]-Table1[[#This Row],[Job Posting Date]] -> 89 | Q9: =Table1[[#This Row],[Join Date]]-Table1[[#This Row],[Hire Date]] -> 10 | R9: =(IF(Table1[[#This Row],[Status]]="Exited",Table1[[#This Row],[Exit Date]]-Table1[[#This Row],[Join Date]],TODAY()-Table1[[#This Row],[Join Date]]))/30 -> 55.566667 | S9: =Table1[[#This Row],[Hire Date]]-Table1[[#This Row],[Job Posting Date]] -> 89 | T9: =Table1[[#This Row],[Time to Onboard]]/Table1[[#This Row],[Time to Fill]]*100 -> 11.235955 | U9: =Table1[[#This Row],[Time to Onboard]]/Table1[[#This Row],[Time to Fill]]*100 -> 11.235955 | V9: =Table1[[#This Row],[Join Date]]-Table1[[#This Row],[Job Posting Date]] -> 99 | W9: =RANDBETWEEN(100,200) -> 106 | X9: =Table1[[#This Row],[Absentee Days]]/Table1[[#This Row],[Total Work Days]]*100 -> 4.2307692 | Y9: =YEAR(Table1[[#This Row],[Join Date]]) -> 2020 | Z9: =IF(Table1[[#This Row],[Status]]="Active",1,0) -> 1 | AA9: =IF(Table1[[#This Row],[Status]]="Exited",Table1[[#This Row],[Recruitment Cost]]+Table1[[#This Row],[Onboarding Cost]]+Table1[[#This Row],[Training Cost]],0) -> 0 | AD9: Overall Onboarding Efficiency Rate | AF9: exit to onboard | AG9: worforce stability index | AH9: Turnover cost estimate
A10: ="E" & TEXT(ROW(A9), "000") -> E009 | B10: {=INDEX(sheet2!$A$2:$A$6, RANDBETWEEN(1, 5))} -> Analytics | C10: =_xlfn.XLOOKUP(Table1[[#This Row],[Department]],sheet2!$A$2:$A$6,sheet2!$B$2:$B$6,_xleta.NA,0) -> Data Analyst | D10: =DATE(RANDBETWEEN(2018, 2022), RANDBETWEEN(1, 12), RANDBETWEEN(1, 28)) -> 44090 | E10: =Table1[[#This Row],[Job Posting Date]]+ RANDBETWEEN(15, 90) -> 44174 | F10: =Table1[[#This Row],[Hire Date]]+ RANDBETWEEN(1, 15) -> 44182 | G10: =IF(RAND() < 0.5, Table1[[#This Row],[Join Date]]+ RANDBETWEEN(30, TODAY()- Table1[[#This Row],[Join Date]]), "-") -> - | H10: =IF(Table1[[#This Row],[Exit Date]]= "-", "Active", "Exited") -> Active | I10: =RANDBETWEEN(1500, 5000) -> 2475 | J10: {=INDEX(sheet2!$C$2:$C$6, RANDBETWEEN(1, 5))} -> Communication Skills | K10: =IF(RAND() < 0.7, "Completed", "Not Completed") -> Completed | L10: 260 | M10: =RANDBETWEEN(0, 20) -> 11 | N10: =CHOOSE(RANDBETWEEN(1, 3), "Male", "Female", "Other") -> Other | O10: =RANDBETWEEN(1200, 2500) -> 1984 | P10: =Table1[[#This Row],[Hire Date]]-Table1[[#This Row],[Job Posting Date]] -> 84 | Q10: =Table1[[#This Row],[Join Date]]-Table1[[#This Row],[Hire Date]] -> 8 | R10: =(IF(Table1[[#This Row],[Status]]="Exited",Table1[[#This Row],[Exit Date]]-Table1[[#This Row],[Join Date]],TODAY()-Table1[[#This Row],[Join Date]]))/30 -> 50.033333 | S10: =Table1[[#This Row],[Hire Date]]-Table1[[#This Row],[Job Posting Date]] -> 84 | T10: =Table1[[#This Row],[Time to Onboard]]/Table1[[#This Row],[Time to Fill]]*100 -> 9.5238095 | U10: =Table1[[#This Row],[Time to Onboard]]/Table1[[#This Row],[Time to Fill]]*100 -> 9.5238095 | V10: =Table1[[#This Row],[Join Date]]-Table1[[#This Row],[Job Posting Date]] -> 92 | W10: =RANDBETWEEN(100,200) -> 195 | X10: =Table1[[#This Row],[Absentee Days]]/Table1[[#This Row],[Total Work Days]]*100 -> 4.2307692 | Y10: =YEAR(Table1[[#This Row],[Join Date]]) -> 2020 | Z10: =IF(Table1[[#This Row],[Status]]="Active",1,0) -> 1 | AA10: =IF(Table1[[#This Row],[Status]]="Exited",Table1[[#This Row],[Recruitment Cost]]+Table1[[#This Row],[Onboarding Cost]]+Table1[[#This Row],[Training Cost]],0) -> 0 | AD10: =(SUM(Timetoonboard) / SUM(Timetofill)) * 100 -> 14.805983 | AF10: =(COUNTIF(Status, "Exited") / COUNTIF(Status, "Active")) * 100 -> 87.969925 | AG10: =(COUNTIF(Status, "Active") / COUNTA(Status)) * 100 -> 52.988048 | AH10: =(AVERAGE(RecruitmentCost)+AVERAGE(Onboardingcost))*COUNTIF(Status,"Exited") -> 396893.48
A11: ="E" & TEXT(ROW(A10), "000") -> E010 | B11: {=INDEX(sheet2!$A$2:$A$6, RANDBETWEEN(1, 5))} -> HR | C11: =_xlfn.XLOOKUP(Table1[[#This Row],[Department]],sheet2!$A$2:$A$6,sheet2!$B$2:$B$6,_xleta.NA,0) -> HR Manager | D11: =DATE(RANDBETWEEN(2018, 2022), RANDBETWEEN(1, 12), RANDBETWEEN(1, 28)) -> 44328 | E11: =Table1[[#This Row],[Job Posting Date]]+ RANDBETWEEN(15, 90) -> 44395 | F11: =Table1[[#This Row],[Hire Date]]+ RANDBETWEEN(1, 15) -> 44406 | G11: =IF(RAND() < 0.5, Table1[[#This Row],[Join Date]]+ RANDBETWEEN(30, TODAY()- Table1[[#This Row],[Join Date]]), "-") -> 44565 | H11: =IF(Table1[[#This Row],[Exit Date]]= "-", "Active", "Exited") -> Exited | I11: =RANDBETWEEN(1500, 5000) -> 3197 | J11: {=INDEX(sheet2!$C$2:$C$6, RANDBETWEEN(1, 5))} -> Advanced Excel Skills | K11: =IF(RAND() < 0.7, "Completed", "Not Completed") -> Completed | L11: 260 | M11: =RANDBETWEEN(0, 20) -> 2 | N11: =CHOOSE(RANDBETWEEN(1, 3), "Male", "Female", "Other") -> Male | O11: =RANDBETWEEN(1200, 2500) -> 2161 | P11: =Table1[[#This Row],[Hire Date]]-Table1[[#This Row],[Job Posting Date]] -> 67 | Q11: =Table1[[#This Row],[Join Date]]-Table1[[#This Row],[Hire Date]] -> 11 | S11: =Table1[[#This Row],[Hire Date]]-Table1[[#This Row],[Job Posting Date]] -> 67 | T11: =Table1[[#This Row],[Time to Onboard]]/Table1[[#This Row],[Time to Fill]]*100 -> 16.41791 | U11: =Table1[[#This Row],[Time to Onboard]]/Table1[[#This Row],[Time to Fill]]*100 -> 16.41791 | V11: =Table1[[#This Row],[Join Date]]-Table1[[#This Row],[Job Posting Date]] -> 78 | W11: =RANDBETWEEN(100,200) -> 191 | X11: =Table1[[#This Row],[Absentee Days]]/Table1[[#This Row],[Total Work Days]]*100 -> 0.76923077 | Y11: =YEAR(Table1[[#This Row],[Join Date]]) -> 2021 | Z11: =IF(Table1[[#This Row],[Status]]="Active",1,0) -> 0 | AA11: =IF(Table1[[#This Row],[Status]]="Exited",Table1[[#This Row],[Recruitment Cost]]+Table1[[#This Row],[Onboarding Cost]]+Table1[[#This Row],[Training Cost]],0) -> 5549
A12: ="E" & TEXT(ROW(A11), "000") -> E011 | B12: {=INDEX(sheet2!$A$2:$A$6, RANDBETWEEN(1, 5))} -> Finance | C12: =_xlfn.XLOOKUP(Table1[[#This Row],[Department]],sheet2!$A$2:$A$6,sheet2!$B$2:$B$6,_xleta.NA,0) -> Finance Manager | D12: =DATE(RANDBETWEEN(2018, 2022), RANDBETWEEN(1, 12), RANDBETWEEN(1, 28)) -> 44534 | E12: =Table1[[#This Row],[Job Posting Date]]+ RANDBETWEEN(15, 90) -> 44603 | F12: =Table1[[#This Row],[Hire Date]]+ RANDBETWEEN(1, 15) -> 44614 | G12: =IF(RAND() < 0.5, Table1[[#This Row],[Join Date]]+ RANDBETWEEN(30, TODAY()- Table1[[#This Row],[Join Date]]), "-") -> 45301 | H12: =IF(Table1[[#This Row],[Exit Date]]= "-", "Active", "Exited") -> Exited | I12: =RANDBETWEEN(1500, 5000) -> 3460 | J12: {=INDEX(sheet2!$C$2:$C$6, RANDBETWEEN(1, 5))} -> Conflict Resolution | K12: =IF(RAND() < 0.7, "Completed", "Not Completed") -> Completed | L12: 260 | M12: =RANDBETWEEN(0, 20) -> 13 | N12: =CHOOSE(RANDBETWEEN(1, 3), "Male", "Female", "Other") -> Other | O12: =RANDBETWEEN(1200, 2500) -> 1545 | P12: =Table1[[#This Row],[Hire Date]]-Table1[[#This Row],[Job Posting Date]] -> 69 | Q12: =Table1[[#This Row],[Join Date]]-Table1[[#This Row],[Hire Date]] -> 11 | R12: =(IF(Table1[[#This Row],[Status]]="Exited",Table1[[#This Row],[Exit Date]]-Table1[[#This Row],[Join Date]],TODAY()-Table1[[#This Row],[Join Date]]))/30 -> 22.9 | S12: =Table1[[#This Row],[Hire Date]]-Table1[[#This Row],[Job Posting Date]] -> 69 | T12: =Table1[[#This Row],[Time to Onboard]]/Table1[[#This Row],[Time to Fill]]*100 -> 15.942029 | U12: =Table1[[#This Row],[Time to Onboard]]/Table1[[#This Row],[Time to Fill]]*100 -> 15.942029 | V12: =Table1[[#This Row],[Join Date]]-Table1[[#This Row],[Job Posting Date]] -> 80 | W12: =RANDBETWEEN(100,200) -> 126 | X12: =Table1[[#This Row],[Absentee Days]]/Table1[[#This Row],[Total Work Days]]*100 -> 5 | Y12: =YEAR(Table1[[#This Row],[Join Date]]) -> 2022 | Z12: =IF(Table1[[#This Row],[Status]]="Active",1,0) -> 0 | AA12: =IF(Table1[[#This Row],[Status]]="Exited",Table1[[#This Row],[Recruitment Cost]]+Table1[[#This Row],[Onboarding Cost]]+Table1[[#This Row],[Training Cost]],0) -> 5131 | AD12: Gender diversity Rate | AF12: Cost of employee turnover
A13: ="E" & TEXT(ROW(A12), "000") -> E012 | B13: {=INDEX(sheet2!$A$2:$A$6, RANDBETWEEN(1, 5))} -> Sales | C13: =_xlfn.XLOOKUP(Table1[[#This Row],[Department]],sheet2!$A$2:$A$6,sheet2!$B$2:$B$6,_xleta.NA,0) -> Marketing Manager | D13: =DATE(RANDBETWEEN(2018, 2022), RANDBETWEEN(1, 12), RANDBETWEEN(1, 28)) -> 43705 | E13: =Table1[[#This Row],[Job Posting Date]]+ RANDBETWEEN(15, 90) -> 43794 | F13: =Table1[[#This Row],[Hire Date]]+ RANDBETWEEN(1, 15) -> 43804 | G13: =IF(RAND() < 0.5, Table1[[#This Row],[Join Date]]+ RANDBETWEEN(30, TODAY()- Table1[[#This Row],[Join Date]]), "-") -> - | H13: =IF(Table1[[#This Row],[Exit Date]]= "-", "Active", "Exited") -> Active | I13: =RANDBETWEEN(1500, 5000) -> 4767 | J13: {=INDEX(sheet2!$C$2:$C$6, RANDBETWEEN(1, 5))} -> Conflict Resolution | K13: =IF(RAND() < 0.7, "Completed", "Not Completed") -> Completed | L13: 260 | M13: =RANDBETWEEN(0, 20) -> 10 | N13: =CHOOSE(RANDBETWEEN(1, 3), "Male", "Female", "Other") -> Male | O13: =RANDBETWEEN(1200, 2500) -> 1622 | P13: =Table1[[#This Row],[Hire Date]]-Table1[[#This Row],[Job Posting Date]] -> 89 | Q13: =Table1[[#This Row],[Join Date]]-Table1[[#This Row],[Hire Date]] -> 10 | R13: =(IF(Table1[[#This Row],[Status]]="Exited",Table1[[#This Row],[Exit Date]]-Table1[[#This Row],[Join Date]],TODAY()-Table1[[#This Row],[Join Date]]))/30 -> 62.633333 | S13: =Table1[[#This Row],[Hire Date]]-Table1[[#This Row],[Job Posting Date]] -> 89 | T13: =Table1[[#This Row],[Time to Onboard]]/Table1[[#This Row],[Time to Fill]]*100 -> 11.235955 | U13: =Table1[[#This Row],[Time to Onboard]]/Table1[[#This Row],[Time to Fill]]*100 -> 11.235955 | V13: =Table1[[#This Row],[Join Date]]-Table1[[#This Row],[Job Posting Date]] -> 99 | W13: =RANDBETWEEN(100,200) -> 140 | X13: =Table1[[#This Row],[Absentee Days]]/Table1[[#This Row],[Total Work Days]]*100 -> 3.8461538 | Y13: =YEAR(Table1[[#This Row],[Join Date]]) -> 2019 | Z13: =IF(Table1[[#This Row],[Status]]="Active",1,0) -> 1 | AA13: =IF(Table1[[#This Row],[Status]]="Exited",Table1[[#This Row],[Recruitment Cost]]+Table1[[#This Row],[Onboarding Cost]]+Table1[[#This Row],[Training Cost]],0) -> 0 | AD13: =COUNTIF(Gender,"Female")/COUNTA(Gender)*100 -> 33.864542 | AF13: =SUM(CostofEmployeeTurnover) -> 609646
A14: ="E" & TEXT(ROW(A13), "000") -> E013 | B14: {=INDEX(sheet2!$A$2:$A$6, RANDBETWEEN(1, 5))} -> Analytics | C14: =_xlfn.XLOOKUP(Table1[[#This Row],[Department]],sheet2!$A$2:$A$6,sheet2!$B$2:$B$6,_xleta.NA,0) -> Data Analyst | D14: =DATE(RANDBETWEEN(2018, 2022), RANDBETWEEN(1, 12), RANDBETWEEN(1, 28)) -> 44869 | E14: =Table1[[#This Row],[Job Posting Date]]+ RANDBETWEEN(15, 90) -> 44958 | F14: =Table1[[#This Row],[Hire Date]]+ RANDBETWEEN(1, 15) -> 44968 | G14: =IF(RAND() < 0.5, Table1[[#This Row],[Join Date]]+ RANDBETWEEN(30, TODAY()- Table1[[#This Row],[Join Date]]), "-") -> - | H14: =IF(Table1[[#This Row],[Exit Date]]= "-", "Active", "Exited") -> Active | I14: =RANDBETWEEN(1500, 5000) -> 3935 | J14: {=INDEX(sheet2!$C$2:$C$6, RANDBETWEEN(1, 5))} -> Conflict Resolution | K14: =IF(RAND() < 0.7, "Completed", "Not Completed") -> Completed | L14: 260 | M14: =RANDBETWEEN(0, 20) -> 1 | N14: =CHOOSE(RANDBETWEEN(1, 3), "Male", "Female", "Other") -> Other | O14: =RANDBETWEEN(1200, 2500) -> 2046 | P14: =Table1[[#This Row],[Hire Date]]-Table1[[#This Row],[Job Posting Date]] -> 89 | Q14: =Table1[[#This Row],[Join Date]]-Table1[[#This Row],[Hire Date]] -> 10 | R14: =(IF(Table1[[#This Row],[Status]]="Exited",Table1[[#This Row],[Exit Date]]-Table1[[#This Row],[Join Date]],TODAY()-Table1[[#This Row],[Join Date]]))/30 -> 23.833333 | S14: =Table1[[#This Row],[Hire Date]]-Table1[[#This Row],[Job Posting Date]] -> 89 | T14: =Table1[[#This Row],[Time to Onboard]]/Table1[[#This Row],[Time to Fill]]*100 -> 11.235955 | U14: =Table1[[#This Row],[Time to Onboard]]/Table1[[#This Row],[Time to Fill]]*100 -> 11.235955 | V14: =Table1[[#This Row],[Join Date]]-Table1[[#This Row],[Job Posting Date]] -> 99 | W14: =RANDBETWEEN(100,200) -> 154 | X14: =Table1[[#This Row],[Absentee Days]]/Table1[[#This Row],[Total Work Days]]*100 -> 0.38461538 | Y14: =YEAR(Table1[[#This Row],[Join Date]]) -> 2023 | Z14: =IF(Table1[[#This Row],[Status]]="Active",1,0) -> 1 | AA14: =IF(Table1[[#This Row],[Status]]="Exited",Table1[[#This Row],[Recruitment Cost]]+Table1[[#This Row],[Onboarding Cost]]+Table1[[#This Row],[Training Cost]],0) -> 0
A15: ="E" & TEXT(ROW(A14), "000") -> E014 | B15: {=INDEX(sheet2!$A$2:$A$6, RANDBETWEEN(1, 5))} -> Finance | C15: =_xlfn.XLOOKUP(Table1[[#This Row],[Department]],sheet2!$A$2:$A$6,sheet2!$B$2:$B$6,_xleta.NA,0) -> Finance Manager | D15: =DATE(RANDBETWEEN(2018, 2022), RANDBETWEEN(1, 12), RANDBETWEEN(1, 28)) -> 43912 | E15: =Table1[[#This Row],[Job Posting Date]]+ RANDBETWEEN(15, 90) -> 43965 | F15: =Table1[[#This Row],[Hire Date]]+ RANDBETWEEN(1, 15) -> 43968 | G15: =IF(RAND() < 0.5, Table1[[#This Row],[Join Date]]+ RANDBETWEEN(30, TODAY()- Table1[[#This Row],[Join Date]]), "-") -> 44836 | H15: =IF(Table1[[#This Row],[Exit Date]]= "-", "Active", "Exited") -> Exited | I15: =RANDBETWEEN(1500, 5000) -> 3768 | J15: {=INDEX(sheet2!$C$2:$C$6, RANDBETWEEN(1, 5))} -> Leadership Development | K15: =IF(RAND() < 0.7, "Completed", "Not Completed") -> Completed | L15: 260 | M15: =RANDBETWEEN(0, 20) -> 19 | N15: =CHOOSE(RANDBETWEEN(1, 3), "Male", "Female", "Other") -> Male | O15: =RANDBETWEEN(1200, 2500) -> 2139 | P15: =Table1[[#This Row],[Hire Date]]-Table1[[#This Row],[Job Posting Date]] -> 53 | Q15: =Table1[[#This Row],[Join Date]]-Table1[[#This Row],[Hire Date]] -> 3 | R15: =(IF(Table1[[#This Row],[Status]]="Exited",Table1[[#This Row],[Exit Date]]-Table1[[#This Row],[Join Date]],TODAY()-Table1[[#This Row],[Join Date]]))/30 -> 28.933333 | S15: =Table1[[#This Row],[Hire Date]]-Table1[[#This Row],[Job Posting Date]] -> 53 | T15: =Table1[[#This Row],[Time to Onboard]]/Table1[[#This Row],[Time to Fill]]*100 -> 5.6603774 | U15: =Table1[[#This Row],[Time to Onboard]]/Table1[[#This Row],[Time to Fill]]*100 -> 5.6603774 | V15: =Table1[[#This Row],[Join Date]]-Table1[[#This Row],[Job Posting Date]] -> 56 | W15: =RANDBETWEEN(100,200) -> 174 | X15: =Table1[[#This Row],[Absentee Days]]/Table1[[#This Row],[Total Work Days]]*100 -> 7.3076923 | Y15: =YEAR(Table1[[#This Row],[Join Date]]) -> 2020 | Z15: =IF(Table1[[#This Row],[Status]]="Active",1,0) -> 0 | AA15: =IF(Table1[[#This Row],[Status]]="Exited",Table1[[#This Row],[Recruitment Cost]]+Table1[[#This Row],[Onboarding Cost]]+Table1[[#This Row],[Training Cost]],0) -> 6081
A16: ="E" & TEXT(ROW(A15), "000") -> E015 | B16: {=INDEX(sheet2!$A$2:$A$6, RANDBETWEEN(1, 5))} -> Analytics | C16: =_xlfn.XLOOKUP(Table1[[#This Row],[Department]],sheet2!$A$2:$A$6,sheet2!$B$2:$B$6,_xleta.NA,0) -> Data Analyst | D16: =DATE(RANDBETWEEN(2018, 2022), RANDBETWEEN(1, 12), RANDBETWEEN(1, 28)) -> 43923 | E16: =Table1[[#This Row],[Job Posting Date]]+ RANDBETWEEN(15, 90) -> 43989 | F16: =Table1[[#This Row],[Hire Date]]+ RANDBETWEEN(1, 15) -> 44003 | G16: =IF(RAND() < 0.5, Table1[[#This Row],[Join Date]]+ RANDBETWEEN(30, TODAY()- Table1[[#This Row],[Join Date]]), "-") -> 44668 | H16: =IF(Table1[[#This Row],[Exit Date]]= "-", "Active", "Exited") -> Exited | I16: =RANDBETWEEN(1500, 5000) -> 3852 | J16: {=INDEX(sheet2!$C$2:$C$6, RANDBETWEEN(1, 5))} -> Leadership Development | K16: =IF(RAND() < 0.7, "Completed", "Not Completed") -> Not Completed | L16: 260 | M16: =RANDBETWEEN(0, 20) -> 14 | N16: =CHOOSE(RANDBETWEEN(1, 3), "Male", "Female", "Other") -> Other | O16: =RANDBETWEEN(1200, 2500) -> 2071 | P16: =Table1[[#This Row],[Hire Date]]-Table1[[#This Row],[Job Posting Date]] -> 66 | Q16: =Table1[[#This Row],[Join Date]]-Table1[[#This Row],[Hire Date]] -> 14 | R16: =(IF(Table1[[#This Row],[Status]]="Exited",Table1[[#This Row],[Exit Date]]-Table1[[#This Row],[Join Date]],TODAY()-Table1[[#This Row],[Join Date]]))/30 -> 22.166667 | S16: =Table1[[#This Row],[Hire Date]]-Table1[[#This Row],[Job Posting Date]] -> 66 | T16: =Table1[[#This Row],[Time to Onboard]]/Table1[[#This Row],[Time to Fill]]*100 -> 21.212121 | U16: =Table1[[#This Row],[Time to Onboard]]/Table1[[#This Row],[Time to Fill]]*100 -> 21.212121 | V16: =Table1[[#This Row],[Join Date]]-Table1[[#This Row],[Job Posting Date]] -> 80 | W16: =RANDBETWEEN(100,200) -> 130 | X16: =Table1[[#This Row],[Absentee Days]]/Table1[[#This Row],[Total Work Days]]*100 -> 5.3846154 | Y16: =YEAR(Table1[[#This Row],[Join Date]]) -> 2020 | Z16: =IF(Table1[[#This Row],[Status]]="Active",1,0) -> 0 | AA16: =IF(Table1[[#This Row],[Status]]="Exited",Table1[[#This Row],[Recruitment Cost]]+Table1[[#This Row],[Onboarding Cost]]+Table1[[#This Row],[Training Cost]],0) -> 6053
A17: ="E" & TEXT(ROW(A16), "000") -> E016 | B17: {=INDEX(sheet2!$A$2:$A$6, RANDBETWEEN(1, 5))} -> IT | C17: =_xlfn.XLOOKUP(Table1[[#This Row],[Department]],sheet2!$A$2:$A$6,sheet2!$B$2:$B$6,_xleta.NA,0) -> Software Engineer | D17: =DATE(RANDBETWEEN(2018, 2022), RANDBETWEEN(1, 12), RANDBETWEEN(1, 28)) -> 44252 | E17: =Table1[[#This Row],[Job Posting Date]]+ RANDBETWEEN(15, 90) -> 44318 | F17: =Table1[[#This Row],[Hire Date]]+ RANDBETWEEN(1, 15) -> 44333 | G17: =IF(RAND() < 0.5, Table1[[#This Row],[Join Date]]+ RANDBETWEEN(30, TODAY()- Table1[[#This Row],[Join Date]]), "-") -> - | H17: =IF(Table1[[#This Row],[Exit Date]]= "-", "Active", "Exited") -> Active | I17: =RANDBETWEEN(1500, 5000) -> 2882 | J17: {=INDEX(sheet2!$C$2:$C$6, RANDBETWEEN(1, 5))} -> Communication Skills | K17: =IF(RAND() < 0.7, "Completed", "Not Completed") -> Completed | L17: 260 | M17: =RANDBETWEEN(0, 20) -> 16 | N17: =CHOOSE(RANDBETWEEN(1, 3), "Male", "Female", "Other") -> Other | O17: =RANDBETWEEN(1200, 2500) -> 1291 | P17: =Table1[[#This Row],[Hire Date]]-Table1[[#This Row],[Job Posting Date]] -> 66 | Q17: =Table1[[#This Row],[Join Date]]-Table1[[#This Row],[Hire Date]] -> 15 | R17: =(IF(Table1[[#This Row],[Status]]="Exited",Table1[[#This Row],[Exit Date]]-Table1[[#This Row],[Join Date]],TODAY()-Table1[[#This Row],[Join Date]]))/30 -> 45 | S17: =Table1[[#This Row],[Hire Date]]-Table1[[#This Row],[Job Posting Date]] -> 66 | T17: =Table1[[#This Row],[Time to Onboard]]/Table1[[#This Row],[Time to Fill]]*100 -> 22.727273 | U17: =Table1[[#This Row],[Time to Onboard]]/Table1[[#This Row],[Time to Fill]]*100 -> 22.727273 | V17: =Table1[[#This Row],[Join Date]]-Table1[[#This Row],[Job Posting Date]] -> 81 | W17: =RANDBETWEEN(100,200) -> 174 | X17: =Table1[[#This Row],[Absentee Days]]/Table1[[#This Row],[Total Work Days]]*100 -> 6.1538462 | Y17: =YEAR(Table1[[#This Row],[Join Date]]) -> 2021 | Z17: =IF(Table1[[#This Row],[Status]]="Active",1,0) -> 1 | AA17: =IF(Table1[[#This Row],[Status]]="Exited",Table1[[#This Row],[Recruitment Cost]]+Table1[[#This Row],[Onboarding Cost]]+Table1[[#This Row],[Training Cost]],0) -> 0
A18: ="E" & TEXT(ROW(A17), "000") -> E017 | B18: {=INDEX(sheet2!$A$2:$A$6, RANDBETWEEN(1, 5))} -> Analytics | C18: =_xlfn.XLOOKUP(Table1[[#This Row],[Department]],sheet2!$A$2:$A$6,sheet2!$B$2:$B$6,_xleta.NA,0) -> Data Analyst | D18: =DATE(RANDBETWEEN(2018, 2022), RANDBETWEEN(1, 12), RANDBETWEEN(1, 28)) -> 43870 | E18: =Table1[[#This Row],[Job Posting Date]]+ RANDBETWEEN(15, 90) -> 43911 | F18: =Table1[[#This Row],[Hire Date]]+ RANDBETWEEN(1, 15) -> 43921 | G18: =IF(RAND() < 0.5, Table1[[#This Row],[Join Date]]+ RANDBETWEEN(30, TODAY()- Table1[[#This Row],[Join Date]]), "-") -> - | H18: =IF(Table1[[#This Row],[Exit Date]]= "-", "Active", "Exited") -> Active | I18: =RANDBETWEEN(1500, 5000) -> 2084 | J18: {=INDEX(sheet2!$C$2:$C$6, RANDBETWEEN(1, 5))} -> Ethics and Responsibilities | K18: =IF(RAND() < 0.7, "Completed", "Not Completed") -> Completed | L18: 260 | M18: =RANDBETWEEN(0, 20) -> 1 | N18: =CHOOSE(RANDBETWEEN(1, 3), "Male", "Female", "Other") -> Female | O18: =RANDBETWEEN(1200, 2500) -> 1850 | P18: =Table1[[#This Row],[Hire Date]]-Table1[[#This Row],[Job Posting Date]] -> 41 | Q18: =Table1[[#This Row],[Join Date]]-Table1[[#This Row],[Hire Date]] -> 10 | R18: =(IF(Table1[[#This Row],[Status]]="Exited",Table1[[#This Row],[Exit Date]]-Table1[[#This Row],[Join Date]],TODAY()-Table1[[#This Row],[Join Date]]))/30 -> 58.733333 | S18: =Table1[[#This Row],[Hire Date]]-Table1[[#This Row],[Job Posting Date]] -> 41 | T18: =Table1[[#This Row],[Time to Onboard]]/Table1[[#This Row],[Time to Fill]]*100 -> 24.390244 | U18: =Table1[[#This Row],[Time to Onboard]]/Table1[[#This Row],[Time to Fill]]*100 -> 24.390244 | V18: =Table1[[#This Row],[Join Date]]-Table1[[#This Row],[Job Posting Date]] -> 51 | W18: =RANDBETWEEN(100,200) -> 131 | X18: =Table1[[#This Row],[Absentee Days]]/Table1[[#This Row],[Total Work Days]]*100 -> 0.38461538 | Y18: =YEAR(Table1[[#This Row],[Join Date]]) -> 2020 | Z18: =IF(Table1[[#This Row],[Status]]="Active",1,0) -> 1 | AA18: =IF(Table1[[#This Row],[Status]]="Exited",Table1[[#This Row],[Recruitment Cost]]+Table1[[#This Row],[Onboarding Cost]]+Table1[[#This Row],[Training Cost]],0) -> 0
A19: ="E" & TEXT(ROW(A18), "000") -> E018 | B19: {=INDEX(sheet2!$A$2:$A$6, RANDBETWEEN(1, 5))} -> Analytics | C19: =_xlfn.XLOOKUP(Table1[[#This Row],[Department]],sheet2!$A$2:$A$6,sheet2!$B$2:$B$6,_xleta.NA,0) -> Data Analyst | D19: =DATE(RANDBETWEEN(2018, 2022), RANDBETWEEN(1, 12), RANDBETWEEN(1, 28)) -> 44256 | E19: =Table1[[#This Row],[Job Posting Date]]+ RANDBETWEEN(15, 90) -> 44298 | F19: =Table1[[#This Row],[Hire Date]]+ RANDBETWEEN(1, 15) -> 44307 | G19: =IF(RAND() < 0.5, Table1[[#This Row],[Join Date]]+ RANDBETWEEN(30, TODAY()- Table1[[#This Row],[Join Date]]), "-") -> - | H19: =IF(Table1[[#This Row],[Exit Date]]= "-", "Active", "Exited") -> Active | I19: =RANDBETWEEN(1500, 5000) -> 4977 | J19: {=INDEX(sheet2!$C$2:$C$6, RANDBETWEEN(1, 5))} -> Communication Skills | K19: =IF(RAND() < 0.7, "Completed", "Not Completed") -> Not Completed | L19: 260 | M19: =RANDBETWEEN(0, 20) -> 7 | N19: =CHOOSE(RANDBETWEEN(1, 3), "Male", "Female", "Other") -> Other | O19: =RANDBETWEEN(1200, 2500) -> 2027 | P19: =Table1[[#This Row],[Hire Date]]-Table1[[#This Row],[Job Posting Date]] -> 42 | Q19: =Table1[[#This Row],[Join Date]]-Table1[[#This Row],[Hire Date]] -> 9 | R19: =(IF(Table1[[#This Row],[Status]]="Exited",Table1[[#This Row],[Exit Date]]-Table1[[#This Row],[Join Date]],TODAY()-Table1[[#This Row],[Join Date]]))/30 -> 45.866667 | S19: =Table1[[#This Row],[Hire Date]]-Table1[[#This Row],[Job Posting Date]] -> 42 | T19: =Table1[[#This Row],[Time to Onboard]]/Table1[[#This Row],[Time to Fill]]*100 -> 21.428571 | U19: =Table1[[#This Row],[Time to Onboard]]/Table1[[#This Row],[Time to Fill]]*100 -> 21.428571 | V19: =Table1[[#This Row],[Join Date]]-Table1[[#This Row],[Job Posting Date]] -> 51 | W19: =RANDBETWEEN(100,200) -> 178 | X19: =Table1[[#This Row],[Absentee Days]]/Table1[[#This Row],[Total Work Days]]*100 -> 2.6923077 | Y19: =YEAR(Table1[[#This Row],[Join Date]]) -> 2021 | Z19: =IF(Table1[[#This Row],[Status]]="Active",1,0) -> 1 | AA19: =IF(Table1[[#This Row],[Status]]="Exited",Table1[[#This Row],[Recruitment Cost]]+Table1[[#This Row],[Onboarding Cost]]+Table1[[#This Row],[Training Cost]],0) -> 0
A20: ="E" & TEXT(ROW(A19), "000") -> E019 | B20: {=INDEX(sheet2!$A$2:$A$6, RANDBETWEEN(1, 5))} -> IT | C20: =_xlfn.XLOOKUP(Table1[[#This Row],[Department]],sheet2!$A$2:$A$6,sheet2!$B$2:$B$6,_xleta.NA,0) -> Software Engineer | D20: =DATE(RANDBETWEEN(2018, 2022), RANDBETWEEN(1, 12), RANDBETWEEN(1, 28)) -> 43438 | E20: =Table1[[#This Row],[Job Posting Date]]+ RANDBETWEEN(15, 90) -> 43508 | F20: =Table1[[#This Row],[Hire Date]]+ RANDBETWEEN(1, 15) -> 43510 | G20: =IF(RAND() < 0.5, Table1[[#This Row],[Join Date]]+ RANDBETWEEN(30, TODAY()- Table1[[#This Row],[Join Date]]), "-") -> - | H20: =IF(Table1[[#This Row],[Exit Date]]= "-", "Active", "Exited") -> Active | I20: =RANDBETWEEN(1500, 5000) -> 3054 | J20: {=INDEX(sheet2!$C$2:$C$6, RANDBETWEEN(1, 5))} -> Leadership Development | K20: =IF(RAND() < 0.7, "Completed", "Not Completed") -> Completed | L20: 260 | M20: =RANDBETWEEN(0, 20) -> 9 | N20: =CHOOSE(RANDBETWEEN(1, 3), "Male", "Female", "Other") -> Female | O20: =RANDBETWEEN(1200, 2500) -> 1928 | P20: =Table1[[#This Row],[Hire Date]]-Table1[[#This Row],[Job Posting Date]] -> 70 | Q20: =Table1[[#This Row],[Join Date]]-Table1[[#This Row],[Hire Date]] -> 2 | R20: =(IF(Table1[[#This Row],[Status]]="Exited",Table1[[#This Row],[Exit Date]]-Table1[[#This Row],[Join Date]],TODAY()-Table1[[#This Row],[Join Date]]))/30 -> 72.433333 | S20: =Table1[[#This Row],[Hire Date]]-Table1[[#This Row],[Job Posting Date]] -> 70 | T20: =Table1[[#This Row],[Time to Onboard]]/Table1[[#This Row],[Time to Fill]]*100 -> 2.8571429 | U20: =Table1[[#This Row],[Time to Onboard]]/Table1[[#This Row],[Time to Fill]]*100 -> 2.8571429 | V20: =Table1[[#This Row],[Join Date]]-Table1[[#This Row],[Job Posting Date]] -> 72 | W20: =RANDBETWEEN(100,200) -> 146 | X20: =Table1[[#This Row],[Absentee Days]]/Table1[[#This Row],[Total Work Days]]*100 -> 3.4615385 | Y20: =YEAR(Table1[[#This Row],[Join Date]]) -> 2019 | Z20: =IF(Table1[[#This Row],[Status]]="Active",1,0) -> 1 | AA20: =IF(Table1[[#This Row],[Status]]="Exited",Table1[[#This Row],[Recruitment Cost]]+Table1[[#This Row],[Onboarding Cost]]+Table1[[#This Row],[Training Cost]],0) -> 0
A21: ="E" & TEXT(ROW(A20), "000") -> E020 | B21: {=INDEX(sheet2!$A$2:$A$6, RANDBETWEEN(1, 5))} -> Analytics | C21: =_xlfn.XLOOKUP(Table1[[#This Row],[Department]],sheet2!$A$2:$A$6,sheet2!$B$2:$B$6,_xleta.NA,0) -> Data Analyst | D21: =DATE(RANDBETWEEN(2018, 2022), RANDBETWEEN(1, 12), RANDBETWEEN(1, 28)) -> 44496 | E21: =Table1[[#This Row],[Job Posting Date]]+ RANDBETWEEN(15, 90) -> 44560 | F21: =Table1[[#This Row],[Hire Date]]+ RANDBETWEEN(1, 15) -> 44563 | G21: =IF(RAND() < 0.5, Table1[[#This Row],[Join Date]]+ RANDBETWEEN(30, TODAY()- Table1[[#This Row],[Join Date]]), "-") -> 44623 | H21: =IF(Table1[[#This Row],[Exit Date]]= "-", "Active", "Exited") -> Exited | I21: =RANDBETWEEN(1500, 5000) -> 2966 | J21: {=INDEX(sheet2!$C$2:$C$6, RANDBETWEEN(1, 5))} -> Leadership Development | K21: =IF(RAND() < 0.7, "Completed", "Not Completed") -> Not Completed | L21: 260 | M21: =RANDBETWEEN(0, 20) -> 9 | N21: =CHOOSE(RANDBETWEEN(1, 3), "Male", "Female", "Other") -> Male | O21: =RANDBETWEEN(1200, 2500) -> 2186 | P21: =Table1[[#This Row],[Hire Date]]-Table1[[#This Row],[Job Posting Date]] -> 64 | Q21: =Table1[[#This Row],[Join Date]]-Table1[[#This Row],[Hire Date]] -> 3 | R21: =(IF(Table1[[#This Row],[Status]]="Exited",Table1[[#This Row],[Exit Date]]-Table1[[#This Row],[Join Date]],TODAY()-Table1[[#This Row],[Join Date]]))/30 -> 2 | S21: =Table1[[#This Row],[Hire Date]]-Table1[[#This Row],[Job Posting Date]] -> 64 | T21: =Table1[[#This Row],[Time to Onboard]]/Table1[[#This Row],[Time to Fill]]*100 -> 4.6875 | U21: =Table1[[#This Row],[Time to Onboard]]/Table1[[#This Row],[Time to Fill]]*100 -> 4.6875 | V21: =Table1[[#This Row],[Join Date]]-Table1[[#This Row],[Job Posting Date]] -> 67 | W21: =RANDBETWEEN(100,200) -> 116 | X21: =Table1[[#This Row],[Absentee Days]]/Table1[[#This Row],[Total Work Days]]*100 -> 3.4615385 | Y21: =YEAR(Table1[[#This Row],[Join Date]]) -> 2022 | Z21: =IF(Table1[[#This Row],[Status]]="Active",1,0) -> 0 | AA21: =IF(Table1[[#This Row],[Status]]="Exited",Table1[[#This Row],[Recruitment Cost]]+Table1[[#This Row],[Onboarding Cost]]+Table1[[#This Row],[Training Cost]],0) -> 5268
A22: ="E" & TEXT(ROW(A21), "000") -> E021 | B22: {=INDEX(sheet2!$A$2:$A$6, RANDBETWEEN(1, 5))} -> Finance | C22: =_xlfn.XLOOKUP(Table1[[#This Row],[Department]],sheet2!$A$2:$A$6,sheet2!$B$2:$B$6,_xleta.NA,0) -> Finance Manager | D22: =DATE(RANDBETWEEN(2018, 2022), RANDBETWEEN(1, 12), RANDBETWEEN(1, 28)) -> 43195 | E22: =Table1[[#This Row],[Job Posting Date]]+ RANDBETWEEN(15, 90) -> 43243 | F22: =Table1[[#This Row],[Hire Date]]+ RANDBETWEEN(1, 15) -> 43257 | G22: =IF(RAND() < 0.5, Table1[[#This Row],[Join Date]]+ RANDBETWEEN(30, TODAY()- Table1[[#This Row],[Join Date]]), "-") -> - | H22: =IF(Table1[[#This Row],[Exit Date]]= "-", "Active", "Exited") -> Active | I22: =RANDBETWEEN(1500, 5000) -> 2685 | J22: {=INDEX(sheet2!$C$2:$C$6, RANDBETWEEN(1, 5))} -> Advanced Excel Skills | K22: =IF(RAND() < 0.7, "Completed", "Not Completed") -> Completed | L22: 260 | M22: =RANDBETWEEN(0, 20) -> 13 | N22: =CHOOSE(RANDBETWEEN(1, 3), "Male", "Female", "Other") -> Other | O22: =RANDBETWEEN(1200, 2500) -> 2150 | P22: =Table1[[#This Row],[Hire Date]]-Table1[[#This Row],[Job Posting Date]] -> 48 | Q22: =Table1[[#This Row],[Join Date]]-Table1[[#This Row],[Hire Date]] -> 14 | R22: =(IF(Table1[[#This Row],[Status]]="Exited",Table1[[#This Row],[Exit Date]]-Table1[[#This Row],[Join Date]],TODAY()-Table1[[#This Row],[Join Date]]))/30 -> 80.866667 | S22: =Table1[[#This Row],[Hire Date]]-Table1[[#This Row],[Job Posting Date]] -> 48 | T22: =Table1[[#This Row],[Time to Onboard]]/Table1[[#This Row],[Time to Fill]]*100 -> 29.166667 | U22: =Table1[[#This Row],[Time to Onboard]]/Table1[[#This Row],[Time to Fill]]*100 -> 29.166667 | V22: =Table1[[#This Row],[Join Date]]-Table1[[#This Row],[Job Posting Date]] -> 62 | W22: =RANDBETWEEN(100,200) -> 141 | X22: =Table1[[#This Row],[Absentee Days]]/Table1[[#This Row],[Total Work Days]]*100 -> 5 | Y22: =YEAR(Table1[[#This Row],[Join Date]]) -> 2018 | Z22: =IF(Table1[[#This Row],[Status]]="Active",1,0) -> 1 | AA22: =IF(Table1[[#This Row],[Status]]="Exited",Table1[[#This Row],[Recruitment Cost]]+Table1[[#This Row],[Onboarding Cost]]+Table1[[#This Row],[Training Cost]],0) -> 0
A23: ="E" & TEXT(ROW(A22), "000") -> E022 | B23: {=INDEX(sheet2!$A$2:$A$6, RANDBETWEEN(1, 5))} -> Finance | C23: =_xlfn.XLOOKUP(Table1[[#This Row],[Department]],sheet2!$A$2:$A$6,sheet2!$B$2:$B$6,_xleta.NA,0) -> Finance Manager | D23: =DATE(RANDBETWEEN(2018, 2022), RANDBETWEEN(1, 12), RANDBETWEEN(1, 28)) -> 43288 | E23: =Table1[[#This Row],[Job Posting Date]]+ RANDBETWEEN(15, 90) -> 43348 | F23: =Table1[[#This Row],[Hire Date]]+ RANDBETWEEN(1, 15) -> 43360 | G23: =IF(RAND() < 0.5, Table1[[#This Row],[Join Date]]+ RANDBETWEEN(30, TODAY()- Table1[[#This Row],[Join Date]]), "-") -> 43745 | H23: =IF(Table1[[#This Row],[Exit Date]]= "-", "Active", "Exited") -> Exited | I23: =RANDBETWEEN(1500, 5000) -> 2177 | J23: {=INDEX(sheet2!$C$2:$C$6, RANDBETWEEN(1, 5))} -> Ethics and Responsibilities | K23: =IF(RAND() < 0.7, "Completed", "Not Completed") -> Completed | L23: 260 | M23: =RANDBETWEEN(0, 20) -> 7 | N23: =CHOOSE(RANDBETWEEN(1, 3), "Male", "Female", "Other") -> Male | O23: =RANDBETWEEN(1200, 2500) -> 2239 | P23: =Table1[[#This Row],[Hire Date]]-Table1[[#This Row],[Job Posting Date]] -> 60 | Q23: =Table1[[#This Row],[Join Date]]-Table1[[#This Row],[Hire Date]] -> 12 | R23: =(IF(Table1[[#This Row],[Status]]="Exited",Table1[[#This Row],[Exit Date]]-Table1[[#This Row],[Join Date]],TODAY()-Table1[[#This Row],[Join Date]]))/30 -> 12.833333 | S23: =Table1[[#This Row],[Hire Date]]-Table1[[#This Row],[Job Posting Date]] -> 60 | T23: =Table1[[#This Row],[Time to Onboard]]/Table1[[#This Row],[Time to Fill]]*100 -> 20 | U23: =Table1[[#This Row],[Time to Onboard]]/Table1[[#This Row],[Time to Fill]]*100 -> 20 | V23: =Table1[[#This Row],[Join Date]]-Table1[[#This Row],[Job Posting Date]] -> 72 | W23: =RANDBETWEEN(100,200) -> 183 | X23: =Table1[[#This Row],[Absentee Days]]/Table1[[#This Row],[Total Work Days]]*100 -> 2.6923077 | Y23: =YEAR(Table1[[#This Row],[Join Date]]) -> 2018 | Z23: =IF(Table1[[#This Row],[Status]]="Active",1,0) -> 0 | AA23: =IF(Table1[[#This Row],[Status]]="Exited",Table1[[#This Row],[Recruitment Cost]]+Table1[[#This Row],[Onboarding Cost]]+Table1[[#This Row],[Training Cost]],0) -> 4599
A24: ="E" & TEXT(ROW(A23), "000") -> E023 | B24: {=INDEX(sheet2!$A$2:$A$6, RANDBETWEEN(1, 5))} -> HR | C24: =_xlfn.XLOOKUP(Table1[[#This Row],[Department]],sheet2!$A$2:$A$6,sheet2!$B$2:$B$6,_xleta.NA,0) -> HR Manager | D24: =DATE(RANDBETWEEN(2018, 2022), RANDBETWEEN(1, 12), RANDBETWEEN(1, 28)) -> 44752 | E24: =Table1[[#This Row],[Job Posting Date]]+ RANDBETWEEN(15, 90) -> 44778 | F24: =Table1[[#This Row],[Hire Date]]+ RANDBETWEEN(1, 15) -> 44780 | G24: =IF(RAND() < 0.5, Table1[[#This Row],[Join Date]]+ RANDBETWEEN(30, TODAY()- Table1[[#This Row],[Join Date]]), "-") -> 45179 | H24: =IF(Table1[[#This Row],[Exit Date]]= "-", "Active", "Exited") -> Exited | I24: =RANDBETWEEN(1500, 5000) -> 2863 | J24: {=INDEX(sheet2!$C$2:$C$6, RANDBETWEEN(1, 5))} -> Communication Skills | K24: =IF(RAND() < 0.7, "Completed", "Not Completed") -> Not Completed | L24: 260 | M24: =RANDBETWEEN(0, 20) -> 9 | N24: =CHOOSE(RANDBETWEEN(1, 3), "Male", "Female", "Other") -> Female | O24: =RANDBETWEEN(1200, 2500) -> 1636 | P24: =Table1[[#This Row],[Hire Date]]-Table1[[#This Row],[Job Posting Date]] -> 26 | Q24: =Table1[[#This Row],[Join Date]]-Table1[[#This Row],[Hire Date]] -> 2 | R24: =(IF(Table1[[#This Row],[Status]]="Exited",Table1[[#This Row],[Exit Date]]-Table1[[#This Row],[Join Date]],TODAY()-Table1[[#This Row],[Join Date]]))/30 -> 13.3 | S24: =Table1[[#This Row],[Hire Date]]-Table1[[#This Row],[Job Posting Date]] -> 26 | T24: =Table1[[#This Row],[Time to Onboard]]/Table1[[#This Row],[Time to Fill]]*100 -> 7.6923077 | U24: =Table1[[#This Row],[Time to Onboard]]/Table1[[#This Row],[Time to Fill]]*100 -> 7.6923077 | V24: =Table1[[#This Row],[Join Date]]-Table1[[#This Row],[Job Posting Date]] -> 28 | W24: =RANDBETWEEN(100,200) -> 161 | X24: =Table1[[#This Row],[Absentee Days]]/Table1[[#This Row],[Total Work Days]]*100 -> 3.4615385 | Y24: =YEAR(Table1[[#This Row],[Join Date]]) -> 2022 | Z24: =IF(Table1[[#This Row],[Status]]="Active",1,0) -> 0 | AA24: =IF(Table1[[#This Row],[Status]]="Exited",Table1[[#This Row],[Recruitment Cost]]+Table1[[#This Row],[Onboarding Cost]]+Table1[[#This Row],[Training Cost]],0) -> 4660
A25: ="E" & TEXT(ROW(A24), "000") -> E024 | B25: {=INDEX(sheet2!$A$2:$A$6, RANDBETWEEN(1, 5))} -> Sales | C25: =_xlfn.XLOOKUP(Table1[[#This Row],[Department]],sheet2!$A$2:$A$6,sheet2!$B$2:$B$6,_xleta.NA,0) -> Marketing Manager | D25: =DATE(RANDBETWEEN(2018, 2022), RANDBETWEEN(1, 12), RANDBETWEEN(1, 28)) -> 44010 | E25: =Table1[[#This Row],[Job Posting Date]]+ RANDBETWEEN(15, 90) -> 44027 | F25: =Table1[[#This Row],[Hire Date]]+ RANDBETWEEN(1, 15) -> 44042 | G25: =IF(RAND() < 0.5, Table1[[#This Row],[Join Date]]+ RANDBETWEEN(30, TODAY()- Table1[[#This Row],[Join Date]]), "-") -> - | H25: =IF(Table1[[#This Row],[Exit Date]]= "-", "Active", "Exited") -> Active | I25: =RANDBETWEEN(1500, 5000) -> 4545 | J25: {=INDEX(sheet2!$C$2:$C$6, RANDBETWEEN(1, 5))} -> Leadership Development | K25: =IF(RAND() < 0.7, "Completed", "Not Completed") -> Completed | L25: 260 | M25: =RANDBETWEEN(0, 20) -> 0 | N25: =CHOOSE(RANDBETWEEN(1, 3), "Male", "Female", "Other") -> Other | O25: =RANDBETWEEN(1200, 2500) -> 1274 | P25: =Table1[[#This Row],[Hire Date]]-Table1[[#This Row],[Job Posting Date]] -> 17 | Q25: =Table1[[#This Row],[Join Date]]-Table1[[#This Row],[Hire Date]] -> 15 | R25: =(IF(Table1[[#This Row],[Status]]="Exited",Table1[[#This Row],[Exit Date]]-Table1[[#This Row],[Join Date]],TODAY()-Table1[[#This Row],[Join Date]]))/30 -> 54.7 | S25: =Table1[[#This Row],[Hire Date]]-Table1[[#This Row],[Job Posting Date]] -> 17 | T25: =Table1[[#This Row],[Time to Onboard]]/Table1[[#This Row],[Time to Fill]]*100 -> 88.235294 | U25: =Table1[[#This Row],[Time to Onboard]]/Table1[[#This Row],[Time to Fill]]*100 -> 88.235294 | V25: =Table1[[#This Row],[Join Date]]-Table1[[#This Row],[Job Posting Date]] -> 32 | W25: =RANDBETWEEN(100,200) -> 154 | X25: =Table1[[#This Row],[Absentee Days]]/Table1[[#This Row],[Total Work Days]]*100 -> 0 | Y25: =YEAR(Table1[[#This Row],[Join Date]]) -> 2020 | Z25: =IF(Table1[[#This Row],[Status]]="Active",1,0) -> 1 | AA25: =IF(Table1[[#This Row],[Status]]="Exited",Table1[[#This Row],[Recruitment Cost]]+Table1[[#This Row],[Onboarding Cost]]+Table1[[#This Row],[Training Cost]],0) -> 0
... A251: ="E" & TEXT(ROW(A250), "000") -> E250 | B251: {=INDEX(sheet2!$A$2:$A$6, RANDBETWEEN(1, 5))} -> Finance | C251: =_xlfn.XLOOKUP(Table1[[#This Row],[Department]],sheet2!$A$2:$A$6,sheet2!$B$2:$B$6,_xleta.NA,0) -> Finance Manager | D251: =DATE(RANDBETWEEN(2018, 2022), RANDBETWEEN(1, 12), RANDBETWEEN(1, 28)) -> 43750 | E251: =Table1[[#This Row],[Job Posting Date]]+ RANDBETWEEN(15, 90) -> 43811 | F251: =Table1[[#This Row],[Hire Date]]+ RANDBETWEEN(1, 15) -> 43817 | G251: =IF(RAND() < 0.5, Table1[[#This Row],[Join Date]]+ RANDBETWEEN(30, TODAY()- Table1[[#This Row],[Join Date]]), "-") -> 44858 | H251: =IF(Table1[[#This Row],[Exit Date]]= "-", "Active", "Exited") -> Exited | I251: =RANDBETWEEN(1500, 5000) -> 2010 | J251: {=INDEX(sheet2!$C$2:$C$6, RANDBETWEEN(1, 5))} -> Communication Skills | K251: =IF(RAND() < 0.7, "Completed", "Not Completed") -> Completed | L251: 260 | M251: =RANDBETWEEN(0, 20) -> 20 | N251: =CHOOSE(RANDBETWEEN(1, 3), "Male", "Female", "Other") -> Female | O251: =RANDBETWEEN(1200, 2500) -> 1584 | P251: =Table1[[#This Row],[Hire Date]]-Table1[[#This Row],[Job Posting Date]] -> 61 | Q251: =Table1[[#This Row],[Join Date]]-Table1[[#This Row],[Hire Date]] -> 6 | R251: =(IF(Table1[[#This Row],[Status]]="Exited",Table1[[#This Row],[Exit Date]]-Table1[[#This Row],[Join Date]],TODAY()-Table1[[#This Row],[Join Date]]))/30 -> 34.7 | S251: =Table1[[#This Row],[Hire Date]]-Table1[[#This Row],[Job Posting Date]] -> 61 | T251: =Table1[[#This Row],[Time to Onboard]]/Table1[[#This Row],[Time to Fill]]*100 -> 9.8360656 | U251: =Table1[[#This Row],[Time to Onboard]]/Table1[[#This Row],[Time to Fill]]*100 -> 9.8360656 | V251: =Table1[[#This Row],[Join Date]]-Table1[[#This Row],[Job Posting Date]] -> 67 | W251: =RANDBETWEEN(100,200) -> 119 | X251: =Table1[[#This Row],[Absentee Days]]/Table1[[#This Row],[Total Work Days]]*100 -> 7.6923077 | Y251: =YEAR(Table1[[#This Row],[Join Date]]) -> 2019 | Z251: =IF(Table1[[#This Row],[Status]]="Active",1,0) -> 0 | AA251: =IF(Table1[[#This Row],[Status]]="Exited",Table1[[#This Row],[Recruitment Cost]]+Table1[[#This Row],[Onboarding Cost]]+Table1[[#This Row],[Training Cost]],0) -> 3713

Sheet sheet2
A1: Department | B1: Job Title | C1: Traning program
A2: IT | B2: Software Engineer | C2: Leadership Development
A3: HR | B3: HR Manager | C3: Advanced Excel Skills
A4: Sales | B4: Marketing Manager | C4: Conflict Resolution
A5: Finance | B5: Finance Manager | C5: Communication Skills
A6: Analytics | B6: Data Analyst | C6: Ethics and Responsibilities

Sheet Pivot table
A3: Row Labels | B3: Average of Time to onboard
A4: Analytics | B4: 7.9622642
A5: Finance | B5: 6.98
A6: HR | B6: 8.4897959
A7: IT | B7: 6.98
A8: Sales | B8: 8.7083333
A9: Grand Total | B9: 7.816
A20: Row Labels | B20: Average of Recruitment Cycle Time
A21: Data Analyst | B21: 51.679245
A22: Finance Manager | B22: 54.04
A23: HR Manager | B23: 50.918367
A24: Marketing Manager | B24: 55.833333
A25: Software Engineer | B25: 57.1
A26: Grand Total | B26: 53.884
A40: Row Labels | B40: Average of Time to fill
A41: Analytics | B41: 51.679245
A42: Finance | B42: 54.04
A43: HR | B43: 50.918367
A44: IT | B44: 57.1
A45: Sales | B45: 55.833333
A46: Grand Total | B46: 53.884
A55: Row Labels | B55: Sum of Total Tenure in M
A56: 2018 | B56: 2122.7667
A57: 2019 | B57: 2138.6667
A58: 2020 | B58: 2155.9667
A59: 2021 | B59: 1368.3333
A60: 2022 | B60: 1333.3333
A61: 2023 | B61: 131.56667
A62: Grand Total | B62: 9250.6333
A68: Row Labels | B68: Sum of Retention Status
A69: Analytics | B69: 18
A70: Finance | B70: 21
A71: HR | B71: 25
A72: IT | B72: 22
A73: Sales | B73: 27
A74: Grand Total | B74: 113
A82: Row Labels | B82: Average of Total Tenure in M
A83: Analytics | B83: 32.216981
A84: Finance | B84: 41.065306
A85: HR | B85: 40.458503
...

Sheet Dashboard
